Workbook

Sheet Dashboard
A1: MEGA KALKULATOR BUDŻETOWY 2026–2027 | DASHBOARD
A4: Instrukcja obsługi:
A5: 1. 'Ustawienia' — parametry: indeksacja 2027, przenoszenie budżetu, cele oszczędnościowe.
A6: 2. 'Budżet 2026' / 'Budżet 2027' — planowane kwoty miesięczne. Rok 2027 wylicza się z 2026 (można nadpisać).
A7: 3. 'Rollover 2026' / 'Rollover 2027' — wpisujesz WYKONANIE; niewydany budżet przechodzi na kolejny miesiąc.
A8: 4. 'Statystyki' — 8 sekcji analitycznych: przepływy, struktura, TOP 10, koszty stałe/zmienne, wskaźniki.
A9: 5. Ten arkusz aktualizuje się automatycznie — wykresy i KPI liczone są z powyższych arkuszy.
A11: PODSUMOWANIE ROCZNE
A12: Rok | B12: Łączne przychody | C12: Wydatki konsumpcyjne | D12: Oszczędności / inwestycje | E12: Bilans (wolne środki) | F12: Stopa oszczędności
A13: Rok 2026 | B13: =Statystyki!B17 -> 7026 | C13: =Statystyki!C17 -> 5924 | D13: =Statystyki!D17 -> 8000 | E13: =Statystyki!E17 -> -6898 | F13: =Statystyki!G17 -> 0.156846
A14: Rok 2027 | B14: =Statystyki!B34 -> 0 | C14: =Statystyki!C34 -> #REF! | D14: =Statystyki!D34 -> 0 | E14: =Statystyki!E34 -> #REF! | F14: =Statystyki!G34 -> 0
A15: RAZEM 2026+2027 | B15: =B13+B14 -> 7026 | C15: =C13+C14 -> #REF! | D15: =D13+D14 -> 8000 | E15: =E13+E14 -> #REF! | F15: =IFERROR((B15-C15)/B15,0) -> 0
A17: KLUCZOWE WSKAŹNIKI 2026
A18: Średni przychód miesięczny | B18: =Statystyki!B67 -> 585.5
A19: Średni wydatek miesięczny | B19: =Statystyki!B68 -> 493.66667
A20: Koszt jednego dnia życia | B20: =Statystyki!B79 -> 16.230137
A21: Największa kategoria kosztowa | B21: =Statystyki!B80 -> FINANSE I OSZCZĘDNOŚCI
A22: Udział największej kategorii | B22: =Statystyki!B81 -> 0.57454754
A23: Roczna stopa oszczędności | B23: =Statystyki!B75 -> 0.156846
A24: Realizacja celu oszczędności | B24: =Statystyki!B77 -> 0
A25: Koszty stałe (rok) | B25: =Statystyki!B61 -> 1624
A26: Koszty zmienne (rok) | B26: =Statystyki!B62 -> 4300
A27: Oszczędności i inwestycje (rok) | B27: =Statystyki!B63 -> 8000
A28: Pozycje bez danych | B28: =Statystyki!B89 -> 34
A29: Niewykorzystany budżet na koniec roku | B29: =Statystyki!E104 -> #REF!
A31: WYKRESY (odświeżają się automatycznie po zmianie danych)

Sheet Statystyki
A1: STATYSTYKI I ANALIZA BUDŻETU
R2: Blok pomocniczy do rankingów (nie usuwaj). Kolumna U = klasyfikacja kosztu, można edytować.
A3: 1. PRZEPŁYWY MIESIĘCZNE 2026
A4: Miesiąc | B4: Przychody | C4: Wydatki konsumpcyjne | D4: Oszczędności / inwestycje | E4: Bilans miesiąca | F4: Bilans skumulowany | G4: Stopa oszczędności | H4: Odchylenie od celu | R4: ='Budżet 2026'!B14 -> Czynsz / Rata kredytu | S4: ='Budżet 2026'!O14 -> 0 | T4: =S4+ROW()/1000000 -> 4e-06 | U4: Stałe | V4: MIESZKANIE
A5: Styczeń | B5: ='Budżet 2026'!C11 -> 0 | C5: ='Budżet 2026'!C26+'Budżet 2026'!C38+'Budżet 2026'!C49+'Budżet 2026'!C57+'Budżet 2026'!C68 -> 0 | D5: ='Budżet 2026'!C76 -> 0 | E5: =B5-C5-D5 -> 0 | F5: =E5 -> 0 | G5: =IFERROR((B5-C5)/B5,0) -> 0 | H5: =D5+E5-#REF! -> #REF! | R5: ='Budżet 2026'!B15 -> Czynsz administracyjny | S5: ='Budżet 2026'!O15 -> 0 | T5: =S5+ROW()/1000000 -> 5e-06 | U5: Stałe | V5: MIESZKANIE
A6: Luty | B6: ='Budżet 2026'!D11 -> 0 | C6: ='Budżet 2026'!D26+'Budżet 2026'!D38+'Budżet 2026'!D49+'Budżet 2026'!D57+'Budżet 2026'!D68 -> 0 | D6: ='Budżet 2026'!D76 -> 0 | E6: =B6-C6-D6 -> 0 | F6: =F5+E6 -> 0 | G6: =IFERROR((B6-C6)/B6,0) -> 0 | H6: =D6+E6-#REF! -> #REF! | R6: ='Budżet 2026'!B16 -> Prąd | S6: ='Budżet 2026'!O16 -> 271 | T6: =S6+ROW()/1000000 -> 271.00001 | U6: Stałe | V6: MIESZKANIE
A7: Marzec | B7: ='Budżet 2026'!E11 -> 0 | C7: ='Budżet 2026'!E26+'Budżet 2026'!E38+'Budżet 2026'!E49+'Budżet 2026'!E57+'Budżet 2026'!E68 -> 0 | D7: ='Budżet 2026'!E76 -> 0 | E7: =B7-C7-D7 -> 0 | F7: =F6+E7 -> 0 | G7: =IFERROR((B7-C7)/B7,0) -> 0 | H7: =D7+E7-#REF! -> #REF! | R7: ='Budżet 2026'!B17 -> Woda i ścieki | S7: ='Budżet 2026'!O17 -> 0 | T7: =S7+ROW()/1000000 -> 7e-06 | U7: Stałe | V7: MIESZKANIE
A8: Kwiecień | B8: ='Budżet 2026'!F11 -> 0 | C8: ='Budżet 2026'!F26+'Budżet 2026'!F38+'Budżet 2026'!F49+'Budżet 2026'!F57+'Budżet 2026'!F68 -> 0 | D8: ='Budżet 2026'!F76 -> 0 | E8: =B8-C8-D8 -> 0 | F8: =F7+E8 -> 0 | G8: =IFERROR((B8-C8)/B8,0) -> 0 | H8: =D8+E8-#REF! -> #REF! | R8: ='Budżet 2026'!B18 -> Gaz | S8: ='Budżet 2026'!O18 -> 200 | T8: =S8+ROW()/1000000 -> 200.00001 | U8: Stałe | V8: MIESZKANIE
A9: Maj | B9: ='Budżet 2026'!G11 -> 0 | C9: ='Budżet 2026'!G26+'Budżet 2026'!G38+'Budżet 2026'!G49+'Budżet 2026'!G57+'Budżet 2026'!G68 -> 0 | D9: ='Budżet 2026'!G76 -> 0 | E9: =B9-C9-D9 -> 0 | F9: =F8+E9 -> 0 | G9: =IFERROR((B9-C9)/B9,0) -> 0 | H9: =D9+E9-#REF! -> #REF! | R9: ='Budżet 2026'!B19 -> Ogrzewanie | S9: ='Budżet 2026'!O19 -> 0 | T9: =S9+ROW()/1000000 -> 9e-06 | U9: Stałe | V9: MIESZKANIE
A10: Czerwiec | B10: ='Budżet 2026'!H11 -> 0 | C10: ='Budżet 2026'!H26+'Budżet 2026'!H38+'Budżet 2026'!H49+'Budżet 2026'!H57+'Budżet 2026'!H68 -> 0 | D10: ='Budżet 2026'!H76 -> 0 | E10: =B10-C10-D10 -> 0 | F10: =F9+E10 -> 0 | G10: =IFERROR((B10-C10)/B10,0) -> 0 | H10: =D10+E10-#REF! -> #REF! | R10: ='Budżet 2026'!B20 -> Wywóz nieczystości | S10: ='Budżet 2026'!O20 -> 0 | T10: =S10+ROW()/1000000 -> 1e-05 | U10: Stałe | V10: MIESZKANIE
A11: Lipiec | B11: ='Budżet 2026'!I11 -> 4063 | C11: ='Budżet 2026'!I26+'Budżet 2026'!I38+'Budżet 2026'!I49+'Budżet 2026'!I57+'Budżet 2026'!I68 -> 5378 | D11: ='Budżet 2026'!I76 -> 8000 | E11: =B11-C11-D11 -> -9315 | F11: =F10+E11 -> -9315 | G11: =IFERROR((B11-C11)/B11,0) -> -0.32365247 | H11: =D11+E11-#REF! -> #REF! | R11: ='Budżet 2026'!B21 -> Internet / Wi-Fi | S11: ='Budżet 2026'!O21 -> 385 | T11: =S11+ROW()/1000000 -> 385.00001 | U11: Stałe | V11: MIESZKANIE
A12: Sierpień | B12: ='Budżet 2026'!J11 -> 2963 | C12: ='Budżet 2026'!J26+'Budżet 2026'!J38+'Budżet 2026'!J49+'Budżet 2026'!J57+'Budżet 2026'!J68 -> 326 | D12: ='Budżet 2026'!J76 -> 0 | E12: =B12-C12-D12 -> 2637 | F12: =F11+E12 -> -6678 | G12: =IFERROR((B12-C12)/B12,0) -> 0.88997638 | H12: =D12+E12-#REF! -> #REF! | R12: ='Budżet 2026'!B22 -> Telewizja | S12: ='Budżet 2026'!O22 -> 0 | T12: =S12+ROW()/1000000 -> 1.2e-05 | U12: Stałe | V12: MIESZKANIE
A13: Wrzesień | B13: ='Budżet 2026'!K11 -> 0 | C13: ='Budżet 2026'!K26+'Budżet 2026'!K38+'Budżet 2026'!K49+'Budżet 2026'!K57+'Budżet 2026'!K68 -> 55 | D13: ='Budżet 2026'!K76 -> 0 | E13: =B13-C13-D13 -> -55 | F13: =F12+E13 -> -6733 | G13: =IFERROR((B13-C13)/B13,0) -> 0 | H13: =D13+E13-#REF! -> #REF! | R13: ='Budżet 2026'!B23 -> Ubezpieczenie nieruchomości | S13: ='Budżet 2026'!O23 -> 0 | T13: =S13+ROW()/1000000 -> 1.3e-05 | U13: Stałe | V13: MIESZKANIE
A14: Październik | B14: ='Budżet 2026'!L11 -> 0 | C14: ='Budżet 2026'!L26+'Budżet 2026'!L38+'Budżet 2026'!L49+'Budżet 2026'!L57+'Budżet 2026'!L68 -> 55 | D14: ='Budżet 2026'!L76 -> 0 | E14: =B14-C14-D14 -> -55 | F14: =F13+E14 -> -6788 | G14: =IFERROR((B14-C14)/B14,0) -> 0 | H14: =D14+E14-#REF! -> #REF! | R14: ='Budżet 2026'!B24 -> Serwis/Naprawy domowe | S14: ='Budżet 2026'!O24 -> 0 | T14: =S14+ROW()/1000000 -> 1.4e-05 | U14: Zmienne | V14: MIESZKANIE
A15: Listopad | B15: ='Budżet 2026'!M11 -> 0 | C15: ='Budżet 2026'!M26+'Budżet 2026'!M38+'Budżet 2026'!M49+'Budżet 2026'!M57+'Budżet 2026'!M68 -> 55 | D15: ='Budżet 2026'!M76 -> 0 | E15: =B15-C15-D15 -> -55 | F15: =F14+E15 -> -6843 | G15: =IFERROR((B15-C15)/B15,0) -> 0 | H15: =D15+E15-#REF! -> #REF! | R15: ='Budżet 2026'!B25 -> Środki czystości/Chemia | S15: ='Budżet 2026'!O25 -> 0 | T15: =S15+ROW()/1000000 -> 1.5e-05 | U15: Zmienne | V15: MIESZKANIE
A16: Grudzień | B16: ='Budżet 2026'!N11 -> 0 | C16: ='Budżet 2026'!N26+'Budżet 2026'!N38+'Budżet 2026'!N49+'Budżet 2026'!N57+'Budżet 2026'!N68 -> 55 | D16: ='Budżet 2026'!N76 -> 0 | E16: =B16-C16-D16 -> -55 | F16: =F15+E16 -> -6898 | G16: =IFERROR((B16-C16)/B16,0) -> 0 | H16: =D16+E16-#REF! -> #REF! | R16: ='Budżet 2026'!B29 -> Paliwo | S16: ='Budżet 2026'!O29 -> 0 | T16: =S16+ROW()/1000000 -> 1.6e-05 | U16: Zmienne | V16: TRANSPORT
A17: RAZEM / ŚREDNIA | B17: =SUM(B5:B16) -> 7026 | C17: =SUM(C5:C16) -> 5924 | D17: =SUM(D5:D16) -> 8000 | E17: =SUM(E5:E16) -> -6898 | F17: =F16 -> -6898 | G17: =IFERROR((B17-C17)/B17,0) -> 0.156846 | H17: =SUM(H5:H16) -> #REF! | R17: ='Budżet 2026'!B30 -> Rata kredytu/leasingu auta | S17: ='Budżet 2026'!O30 -> 0 | T17: =S17+ROW()/1000000 -> 1.7e-05 | U17: Stałe | V17: TRANSPORT
R18: ='Budżet 2026'!B31 -> Ubezpieczenie (OC/AC) | S18: ='Budżet 2026'!O31 -> 0 | T18: =S18+ROW()/1000000 -> 1.8e-05 | U18: Stałe | V18: TRANSPORT
R19: ='Budżet 2026'!B32 -> Przegląd techniczny / Serwis | S19: ='Budżet 2026'!O32 -> 0 | T19: =S19+ROW()/1000000 -> 1.9e-05 | U19: Zmienne | V19: TRANSPORT
A20: 2. PRZEPŁYWY MIESIĘCZNE 2027 | R20: ='Budżet 2026'!B33 -> Opony (wymiana/serwis) | S20: ='Budżet 2026'!O33 -> 0 | T20: =S20+ROW()/1000000 -> 2e-05 | U20: Zmienne | V20: TRANSPORT
A21: Miesiąc | B21: Przychody | C21: Wydatki konsumpcyjne | D21: Oszczędności / inwestycje | E21: Bilans miesiąca | F21: Bilans skumulowany | G21: Stopa oszczędności | H21: Odchylenie od celu | R21: ='Budżet 2026'!B34 -> Bilety komunikacji miejskiej / PKP | S21: ='Budżet 2026'!O34 -> 50 | T21: =S21+ROW()/1000000 -> 50.000021 | U21: Zmienne | V21: TRANSPORT
A22: Styczeń | B22: ='Budżet 2027'!C11 -> 0 | C22: ='Budżet 2027'!C26+'Budżet 2027'!C38+'Budżet 2027'!C49+'Budżet 2027'!C57+'Budżet 2027'!C68 -> #REF! | D22: ='Budżet 2027'!C76 -> 0 | E22: =B22-C22-D22 -> #REF! | F22: =E22 -> #REF! | G22: =IFERROR((B22-C22)/B22,0) -> 0 | H22: =D22+E22-#REF! -> #REF! | R22: ='Budżet 2026'!B35 -> Taxi / Uber / Bolt | S22: ='Budżet 2026'!O35 -> 0 | T22: =S22+ROW()/1000000 -> 2.2e-05 | U22: Zmienne | V22: TRANSPORT
A23: Luty | B23: ='Budżet 2027'!D11 -> 0 | C23: ='Budżet 2027'!D26+'Budżet 2027'!D38+'Budżet 2027'!D49+'Budżet 2027'!D57+'Budżet 2027'!D68 -> #REF! | D23: ='Budżet 2027'!D76 -> 0 | E23: =B23-C23-D23 -> #REF! | F23: =F22+E23 -> #REF! | G23: =IFERROR((B23-C23)/B23,0) -> 0 | H23: =D23+E23-#REF! -> #REF! | R23: ='Budżet 2026'!B36 -> Parkingi / Autostrady | S23: ='Budżet 2026'!O36 -> 0 | T23: =S23+ROW()/1000000 -> 2.3e-05 | U23: Zmienne | V23: TRANSPORT
A24: Marzec | B24: ='Budżet 2027'!E11 -> 0 | C24: ='Budżet 2027'!E26+'Budżet 2027'!E38+'Budżet 2027'!E49+'Budżet 2027'!E57+'Budżet 2027'!E68 -> #REF! | D24: ='Budżet 2027'!E76 -> 0 | E24: =B24-C24-D24 -> #REF! | F24: =F23+E24 -> #REF! | G24: =IFERROR((B24-C24)/B24,0) -> 0 | H24: =D24+E24-#REF! -> #REF! | R24: ='Budżet 2026'!B37 -> Akcesoria samochodowe | S24: ='Budżet 2026'!O37 -> 0 | T24: =S24+ROW()/1000000 -> 2.4e-05 | U24: Zmienne | V24: TRANSPORT
A25: Kwiecień | B25: ='Budżet 2027'!F11 -> 0 | C25: ='Budżet 2027'!F26+'Budżet 2027'!F38+'Budżet 2027'!F49+'Budżet 2027'!F57+'Budżet 2027'!F68 -> #REF! | D25: ='Budżet 2027'!F76 -> 0 | E25: =B25-C25-D25 -> #REF! | F25: =F24+E25 -> #REF! | G25: =IFERROR((B25-C25)/B25,0) -> 0 | H25: =D25+E25-#REF! -> #REF! | R25: ='Budżet 2026'!B41 -> Zakupy spożywcze (market) | S25: ='Budżet 2026'!O41 -> 500 | T25: =S25+ROW()/1000000 -> 500.00002 | U25: Zmienne | V25: ŻYCIE I ZDROWIE
A26: Maj | B26: ='Budżet 2027'!G11 -> 0 | C26: ='Budżet 2027'!G26+'Budżet 2027'!G38+'Budżet 2027'!G49+'Budżet 2027'!G57+'Budżet 2027'!G68 -> #REF! | D26: ='Budżet 2027'!G76 -> 0 | E26: =B26-C26-D26 -> #REF! | F26: =F25+E26 -> #REF! | G26: =IFERROR((B26-C26)/B26,0) -> 0 | H26: =D26+E26-#REF! -> #REF! | R26: ='Budżet 2026'!B42 -> Jedzenie na mieście / Catering | S26: ='Budżet 2026'!O42 -> 300 | T26: =S26+ROW()/1000000 -> 300.00003 | U26: Zmienne | V26: ŻYCIE I ZDROWIE
A27: Czerwiec | B27: ='Budżet 2027'!H11 -> 0 | C27: ='Budżet 2027'!H26+'Budżet 2027'!H38+'Budżet 2027'!H49+'Budżet 2027'!H57+'Budżet 2027'!H68 -> #REF! | D27: ='Budżet 2027'!H76 -> 0 | E27: =B27-C27-D27 -> #REF! | F27: =F26+E27 -> #REF! | G27: =IFERROR((B27-C27)/B27,0) -> 0 | H27: =D27+E27-#REF! -> #REF! | R27: ='Budżet 2026'!B43 -> Prywatne wizyty lekarskie | S27: ='Budżet 2026'!O43 -> 2000 | T27: =S27+ROW()/1000000 -> 2000 | U27: Zmienne | V27: ŻYCIE I ZDROWIE
A28: Lipiec | B28: ='Budżet 2027'!I11 -> 0 | C28: ='Budżet 2027'!I26+'Budżet 2027'!I38+'Budżet 2027'!I49+'Budżet 2027'!I57+'Budżet 2027'!I68 -> #REF! | D28: ='Budżet 2027'!I76 -> 0 | E28: =B28-C28-D28 -> #REF! | F28: =F27+E28 -> #REF! | G28: =IFERROR((B28-C28)/B28,0) -> 0 | H28: =D28+E28-#REF! -> #REF! | R28: ='Budżet 2026'!B44 -> Leki i suplementy | S28: ='Budżet 2026'!O44 -> 0 | T28: =S28+ROW()/1000000 -> 2.8e-05 | U28: Zmienne | V28: ŻYCIE I ZDROWIE
A29: Sierpień | B29: ='Budżet 2027'!J11 -> 0 | C29: ='Budżet 2027'!J26+'Budżet 2027'!J38+'Budżet 2027'!J49+'Budżet 2027'!J57+'Budżet 2027'!J68 -> #REF! | D29: ='Budżet 2027'!J76 -> 0 | E29: =B29-C29-D29 -> #REF! | F29: =F28+E29 -> #REF! | G29: =IFERROR((B29-C29)/B29,0) -> 0 | H29: =D29+E29-#REF! -> #REF! | R29: ='Budżet 2026'!B45 -> Dentysta | S29: ='Budżet 2026'!O45 -> 0 | T29: =S29+ROW()/1000000 -> 2.9e-05 | U29: Zmienne | V29: ŻYCIE I ZDROWIE
A30: Wrzesień | B30: ='Budżet 2027'!K11 -> 0 | C30: ='Budżet 2027'!K26+'Budżet 2027'!K38+'Budżet 2027'!K49+'Budżet 2027'!K57+'Budżet 2027'!K68 -> #REF! | D30: ='Budżet 2027'!K76 -> 0 | E30: =B30-C30-D30 -> #REF! | F30: =F29+E30 -> #REF! | G30: =IFERROR((B30-C30)/B30,0) -> 0 | H30: =D30+E30-#REF! -> #REF! | R30: ='Budżet 2026'!B46 -> Karnet sportowy / Siłownia | S30: ='Budżet 2026'!O46 -> 0 | T30: =S30+ROW()/1000000 -> 3e-05 | U30: Stałe | V30: ŻYCIE I ZDROWIE
A31: Październik | B31: ='Budżet 2027'!L11 -> 0 | C31: ='Budżet 2027'!L26+'Budżet 2027'!L38+'Budżet 2027'!L49+'Budżet 2027'!L57+'Budżet 2027'!L68 -> #REF! | D31: ='Budżet 2027'!L76 -> 0 | E31: =B31-C31-D31 -> #REF! | F31: =F30+E31 -> #REF! | G31: =IFERROR((B31-C31)/B31,0) -> 0 | H31: =D31+E31-#REF! -> #REF! | R31: ='Budżet 2026'!B47 -> Kosmetyczka / Fryzjer | S31: ='Budżet 2026'!O47 -> 0 | T31: =S31+ROW()/1000000 -> 3.1e-05 | U31: Zmienne | V31: ŻYCIE I ZDROWIE
A32: Listopad | B32: ='Budżet 2027'!M11 -> 0 | C32: ='Budżet 2027'!M26+'Budżet 2027'!M38+'Budżet 2027'!M49+'Budżet 2027'!M57+'Budżet 2027'!M68 -> #REF! | D32: ='Budżet 2027'!M76 -> 0 | E32: =B32-C32-D32 -> #REF! | F32: =F31+E32 -> #REF! | G32: =IFERROR((B32-C32)/B32,0) -> 0 | H32: =D32+E32-#REF! -> #REF! | R32: ='Budżet 2026'!B48 -> Odzież i obuwie | S32: ='Budżet 2026'!O48 -> 0 | T32: =S32+ROW()/1000000 -> 3.2e-05 | U32: Zmienne | V32: ŻYCIE I ZDROWIE
A33: Grudzień | B33: ='Budżet 2027'!N11 -> 0 | C33: ='Budżet 2027'!N26+'Budżet 2027'!N38+'Budżet 2027'!N49+'Budżet 2027'!N57+'Budżet 2027'!N68 -> #REF! | D33: ='Budżet 2027'!N76 -> 0 | E33: =B33-C33-D33 -> #REF! | F33: =F32+E33 -> #REF! | G33: =IFERROR((B33-C33)/B33,0) -> 0 | H33: =D33+E33-#REF! -> #REF! | R33: ='Budżet 2026'!B52 -> Czesne za studia / Szkołę | S33: ='Budżet 2026'!O52 -> 768 | T33: =S33+ROW()/1000000 -> 768.00003 | U33: Stałe | V33: ROZWÓJ I EDUKACJA
A34: RAZEM / ŚREDNIA | B34: =SUM(B22:B33) -> 0 | C34: =SUM(C22:C33) -> #REF! | D34: =SUM(D22:D33) -> 0 | E34: =SUM(E22:E33) -> #REF! | F34: =F33 -> #REF! | G34: =IFERROR((B34-C34)/B34,0) -> 0 | H34: =SUM(H22:H33) -> #REF! | R34: ='Budżet 2026'!B53 -> Kursy online / Szkolenia | S34: ='Budżet 2026'!O53 -> 0 | T34: =S34+ROW()/1000000 -> 3.4e-05 | U34: Zmienne | V34: ROZWÓJ I EDUKACJA
R35: ='Budżet 2026'!B54 -> Książki / E-booki | S35: ='Budżet 2026'!O54 -> 0 | T35: =S35+ROW()/1000000 -> 3.5e-05 | U35: Zmienne | V35: ROZWÓJ I EDUKACJA
A36: 3. STRUKTURA WYDATKÓW WEDŁUG KATEGORII | R36: ='Budżet 2026'!B55 -> Subskrypcje edukacyjne | S36: ='Budżet 2026'!O55 -> 0 | T36: =S36+ROW()/1000000 -> 3.6e-05 | U36: Stałe | V36: ROZWÓJ I EDUKACJA
A37: Kategoria | B37: Rok 2026 | C37: % wydatków 2026 | D37: Średnio / miesiąc | E37: Rok 2027 | F37: Zmiana 2027 vs 2026 | G37: Miesiąc max | H37: Miesiąc min | R37: ='Budżet 2026'!B56 -> Sprzęt edukacyjny (laptop, tablet) | S37: ='Budżet 2026'!O56 -> 0 | T37: =S37+ROW()/1000000 -> 3.7e-05 | U37: Zmienne | V37: ROZWÓJ I EDUKACJA
A38: MIESZKANIE | B38: ='Budżet 2026'!O26 -> 856 | C38: =IFERROR(B38/$B$44,0) -> 0.061476587 | D38: =B38/12 -> 71.333333 | E38: ='Budżet 2027'!O26 -> 0 | F38: =IFERROR(E38/B38-1,0) -> -1 | G38: =MAX('Budżet 2026'!C26:N26) -> 326 | H38: =MIN('Budżet 2026'!C26:N26) -> 0 | R38: ='Budżet 2026'!B60 -> Netflix / Disney+ / Spotify | S38: ='Budżet 2026'!O60 -> 0 | T38: =S38+ROW()/1000000 -> 3.8e-05 | U38: Stałe | V38: ROZRYWKA I INNE
A39: TRANSPORT | B39: ='Budżet 2026'!O38 -> 50 | C39: =IFERROR(B39/$B$44,0) -> 0.0035909221 | D39: =B39/12 -> 4.1666667 | E39: ='Budżet 2027'!O38 -> 0 | F39: =IFERROR(E39/B39-1,0) -> -1 | G39: =MAX('Budżet 2026'!C38:N38) -> 50 | H39: =MIN('Budżet 2026'!C38:N38) -> 0 | R39: ='Budżet 2026'!B61 -> Kino / Teatr / Koncerty | S39: ='Budżet 2026'!O61 -> 100 | T39: =S39+ROW()/1000000 -> 100.00004 | U39: Zmienne | V39: ROZRYWKA I INNE
A40: ŻYCIE I ZDROWIE | B40: ='Budżet 2026'!O49 -> 2800 | C40: =IFERROR(B40/$B$44,0) -> 0.20109164 | D40: =B40/12 -> 233.33333 | E40: ='Budżet 2027'!O49 -> #REF! | F40: =IFERROR(E40/B40-1,0) -> 0 | G40: =MAX('Budżet 2026'!C49:N49) -> 2800 | H40: =MIN('Budżet 2026'!C49:N49) -> 0 | R40: ='Budżet 2026'!B62 -> Hobby / Akcesoria | S40: ='Budżet 2026'!O62 -> 0 | T40: =S40+ROW()/1000000 -> 4e-05 | U40: Zmienne | V40: ROZRYWKA I INNE
...

Sheet Budżet 2026
A1: Kategoria | B1: Szczegółowa pozycja | C1: Styczeń | D1: Luty | E1: Marzec | F1: Kwiecień | G1: Maj | H1: Czerwiec | I1: Lipiec | J1: Sierpień | K1: Wrzesień | L1: Październik | M1: Listopad | N1: Grudzień | O1: SUMA ROK
A2: PRZYCHODY
A3: PRZYCHODY | B3: Wynagrodzenie (etat/podstawa) | O3: =SUM(C3:N3) -> 0
A4: PRZYCHODY | B4: Premie/Bonusy | O4: =SUM(C4:N4) -> 0
A5: PRZYCHODY | B5: Działalność gospodarcza (netto) | O5: =SUM(C5:N5) -> 0
A6: PRZYCHODY | B6: Freelance / Zlecenia | O6: =SUM(C6:N6) -> 0
A7: PRZYCHODY | B7: Dochód pasywny (dywidendy/najem) | O7: =SUM(C7:N7) -> 0
A8: PRZYCHODY | B8: Świadczenia (800+, alimenty) | O8: =SUM(C8:N8) -> 0
A9: PRZYCHODY | B9: Zwrot podatku | O9: =SUM(C9:N9) -> 0
A10: PRZYCHODY | B10: Inne przychody | I10: =1100 + 2963 -> 4063 | J10: 2963 | O10: =SUM(C10:N10) -> 7026
A11: PRZYCHODY | B11: RAZEM PRZYCHODY | C11: =SUM(C3:C10) -> 0 | D11: =SUM(D3:D10) -> 0 | E11: =SUM(E3:E10) -> 0 | F11: =SUM(F3:F10) -> 0 | G11: =SUM(G3:G10) -> 0 | H11: =SUM(H3:H10) -> 0 | I11: =SUM(I3:I10) -> 4063 | J11: =SUM(J3:J10) -> 2963 | ... O11: =SUM(O3:O10) -> 7026
A13: MIESZKANIE
A14: MIESZKANIE | B14: Czynsz / Rata kredytu | O14: =SUM(C14:N14) -> 0
A15: MIESZKANIE | B15: Czynsz administracyjny | O15: =SUM(C15:N15) -> 0
A16: MIESZKANIE | B16: Prąd | J16: 271 | O16: =SUM(C16:N16) -> 271
A17: MIESZKANIE | B17: Woda i ścieki | O17: =SUM(C17:N17) -> 0
A18: MIESZKANIE | B18: Gaz | I18: 200 | O18: =SUM(C18:N18) -> 200
A19: MIESZKANIE | B19: Ogrzewanie | O19: =SUM(C19:N19) -> 0
A20: MIESZKANIE | B20: Wywóz nieczystości | O20: =SUM(C20:N20) -> 0
A21: MIESZKANIE | B21: Internet / Wi-Fi | I21: 110 | J21: 55 | K21: 55 | L21: 55 | M21: 55 | N21: 55 | O21: =SUM(C21:N21) -> 385
A22: MIESZKANIE | B22: Telewizja | O22: =SUM(C22:N22) -> 0
A23: MIESZKANIE | B23: Ubezpieczenie nieruchomości | O23: =SUM(C23:N23) -> 0
A24: MIESZKANIE | B24: Serwis/Naprawy domowe | O24: =SUM(C24:N24) -> 0
A25: MIESZKANIE | B25: Środki czystości/Chemia | O25: =SUM(C25:N25) -> 0
A26: MIESZKANIE | B26: RAZEM MIESZKANIE | C26: =SUM(C14:C25) -> 0 | D26: =SUM(D14:D25) -> 0 | E26: =SUM(E14:E25) -> 0 | F26: =SUM(F14:F25) -> 0 | G26: =SUM(G14:G25) -> 0 | H26: =SUM(H14:H25) -> 0 | I26: =SUM(I14:I25) -> 310 | J26: =SUM(J14:J25) -> 326 | ... O26: =SUM(O14:O25) -> 856
A28: TRANSPORT
A29: TRANSPORT | B29: Paliwo | O29: =SUM(C29:N29) -> 0
A30: TRANSPORT | B30: Rata kredytu/leasingu auta | O30: =SUM(C30:N30) -> 0
A31: TRANSPORT | B31: Ubezpieczenie (OC/AC) | O31: =SUM(C31:N31) -> 0
A32: TRANSPORT | B32: Przegląd techniczny / Serwis | O32: =SUM(C32:N32) -> 0
A33: TRANSPORT | B33: Opony (wymiana/serwis) | O33: =SUM(C33:N33) -> 0
A34: TRANSPORT | B34: Bilety komunikacji miejskiej / PKP | I34: 50 | O34: =SUM(C34:N34) -> 50
A35: TRANSPORT | B35: Taxi / Uber / Bolt | O35: =SUM(C35:N35) -> 0
A36: TRANSPORT | B36: Parkingi / Autostrady | O36: =SUM(C36:N36) -> 0
A37: TRANSPORT | B37: Akcesoria samochodowe | O37: =SUM(C37:N37) -> 0
A38: TRANSPORT | B38: RAZEM TRANSPORT | C38: =SUM(C29:C37) -> 0 | D38: =SUM(D29:D37) -> 0 | E38: =SUM(E29:E37) -> 0 | F38: =SUM(F29:F37) -> 0 | G38: =SUM(G29:G37) -> 0 | H38: =SUM(H29:H37) -> 0 | I38: =SUM(I29:I37) -> 50 | J38: =SUM(J29:J37) -> 0 | ... O38: =SUM(O29:O37) -> 50
A40: ŻYCIE I ZDROWIE
A41: ŻYCIE I ZDROWIE | B41: Zakupy spożywcze (market) | I41: 500 | O41: =SUM(C41:N41) -> 500
A42: ŻYCIE I ZDROWIE | B42: Jedzenie na mieście / Catering | I42: 300 | O42: =SUM(C42:N42) -> 300
A43: ŻYCIE I ZDROWIE | B43: Prywatne wizyty lekarskie | I43: 2000 | O43: =SUM(C43:N43) -> 2000
...

Sheet Budżet 2027
A1: Kategoria | B1: Szczegółowa pozycja | C1: Styczeń | D1: Luty | E1: Marzec | F1: Kwiecień | G1: Maj | H1: Czerwiec | I1: Lipiec | J1: Sierpień | K1: Wrzesień | L1: Październik | M1: Listopad | N1: Grudzień | O1: SUMA ROK
A2: PRZYCHODY
A3: PRZYCHODY | B3: Wynagrodzenie (etat/podstawa) | O3: =SUM(C3:N3) -> 0
A4: PRZYCHODY | B4: Premie/Bonusy | O4: =SUM(C4:N4) -> 0
A5: PRZYCHODY | B5: Działalność gospodarcza (netto) | O5: =SUM(C5:N5) -> 0
A6: PRZYCHODY | B6: Freelance / Zlecenia | O6: =SUM(C6:N6) -> 0
A7: PRZYCHODY | B7: Dochód pasywny (dywidendy/najem) | O7: =SUM(C7:N7) -> 0
A8: PRZYCHODY | B8: Świadczenia (800+, alimenty) | O8: =SUM(C8:N8) -> 0
A9: PRZYCHODY | B9: Zwrot podatku | O9: =SUM(C9:N9) -> 0
A10: PRZYCHODY | B10: Inne przychody | O10: =SUM(C10:N10) -> 0
A11: PRZYCHODY | B11: RAZEM PRZYCHODY | C11: =SUM(C3:C10) -> 0 | D11: =SUM(D3:D10) -> 0 | E11: =SUM(E3:E10) -> 0 | F11: =SUM(F3:F10) -> 0 | G11: =SUM(G3:G10) -> 0 | H11: =SUM(H3:H10) -> 0 | I11: =SUM(I3:I10) -> 0 | J11: =SUM(J3:J10) -> 0 | ... O11: =SUM(O3:O10) -> 0
A13: MIESZKANIE
A14: MIESZKANIE | B14: Czynsz / Rata kredytu | O14: =SUM(C14:N14) -> 0
A15: MIESZKANIE | B15: Czynsz administracyjny | O15: =SUM(C15:N15) -> 0
A16: MIESZKANIE | B16: Prąd | O16: =SUM(C16:N16) -> 0
A17: MIESZKANIE | B17: Woda i ścieki | O17: =SUM(C17:N17) -> 0
A18: MIESZKANIE | B18: Gaz | O18: =SUM(C18:N18) -> 0
A19: MIESZKANIE | B19: Ogrzewanie | O19: =SUM(C19:N19) -> 0
A20: MIESZKANIE | B20: Wywóz nieczystości | O20: =SUM(C20:N20) -> 0
A21: MIESZKANIE | B21: Internet / Wi-Fi | O21: =SUM(C21:N21) -> 0
A22: MIESZKANIE | B22: Telewizja | O22: =SUM(C22:N22) -> 0
A23: MIESZKANIE | B23: Ubezpieczenie nieruchomości | O23: =SUM(C23:N23) -> 0
A24: MIESZKANIE | B24: Serwis/Naprawy domowe | O24: =SUM(C24:N24) -> 0
A25: MIESZKANIE | B25: Środki czystości/Chemia | O25: =SUM(C25:N25) -> 0
A26: MIESZKANIE | B26: RAZEM MIESZKANIE | C26: =SUM(C14:C25) -> 0 | D26: =SUM(D14:D25) -> 0 | E26: =SUM(E14:E25) -> 0 | F26: =SUM(F14:F25) -> 0 | G26: =SUM(G14:G25) -> 0 | H26: =SUM(H14:H25) -> 0 | I26: =SUM(I14:I25) -> 0 | J26: =SUM(J14:J25) -> 0 | ... O26: =SUM(O14:O25) -> 0
A28: TRANSPORT
A29: TRANSPORT | B29: Paliwo | O29: =SUM(C29:N29) -> 0
A30: TRANSPORT | B30: Rata kredytu/leasingu auta | O30: =SUM(C30:N30) -> 0
A31: TRANSPORT | B31: Ubezpieczenie (OC/AC) | O31: =SUM(C31:N31) -> 0
A32: TRANSPORT | B32: Przegląd techniczny / Serwis | O32: =SUM(C32:N32) -> 0
A33: TRANSPORT | B33: Opony (wymiana/serwis) | O33: =SUM(C33:N33) -> 0
A34: TRANSPORT | B34: Bilety komunikacji miejskiej / PKP | O34: =SUM(C34:N34) -> 0
A35: TRANSPORT | B35: Taxi / Uber / Bolt | O35: =SUM(C35:N35) -> 0
A36: TRANSPORT | B36: Parkingi / Autostrady | O36: =SUM(C36:N36) -> 0
A37: TRANSPORT | B37: Akcesoria samochodowe | O37: =SUM(C37:N37) -> 0
A38: TRANSPORT | B38: RAZEM TRANSPORT | C38: =SUM(C29:C37) -> 0 | D38: =SUM(D29:D37) -> 0 | E38: =SUM(E29:E37) -> 0 | F38: =SUM(F29:F37) -> 0 | G38: =SUM(G29:G37) -> 0 | H38: =SUM(H29:H37) -> 0 | I38: =SUM(I29:I37) -> 0 | J38: =SUM(J29:J37) -> 0 | ... O38: =SUM(O29:O37) -> 0
A40: ŻYCIE I ZDROWIE
A41: ŻYCIE I ZDROWIE | B41: Zakupy spożywcze (market) | C41: ='Budżet 2026'!C41*(1+#REF!) -> #REF! | D41: ='Budżet 2026'!D41*(1+#REF!) -> #REF! | E41: ='Budżet 2026'!E41*(1+#REF!) -> #REF! | F41: ='Budżet 2026'!F41*(1+#REF!) -> #REF! | G41: ='Budżet 2026'!G41*(1+#REF!) -> #REF! | H41: ='Budżet 2026'!H41*(1+#REF!) -> #REF! | I41: ='Budżet 2026'!I41*(1+#REF!) -> #REF! | J41: ='Budżet 2026'!J41*(1+#REF!) -> #REF! | ... N41: ='Budżet 2026'!N41*(1+#REF!) -> #REF! | O41: =SUM(C41:N41) -> #REF!
A42: ŻYCIE I ZDROWIE | B42: Jedzenie na mieście / Catering | C42: ='Budżet 2026'!C42*(1+#REF!) -> #REF! | D42: ='Budżet 2026'!D42*(1+#REF!) -> #REF! | E42: ='Budżet 2026'!E42*(1+#REF!) -> #REF! | F42: ='Budżet 2026'!F42*(1+#REF!) -> #REF! | G42: ='Budżet 2026'!G42*(1+#REF!) -> #REF! | H42: ='Budżet 2026'!H42*(1+#REF!) -> #REF! | I42: ='Budżet 2026'!I42*(1+#REF!) -> #REF! | J42: ='Budżet 2026'!J42*(1+#REF!) -> #REF! | ... N42: ='Budżet 2026'!N42*(1+#REF!) -> #REF! | O42: =SUM(C42:N42) -> #REF!
A43: ŻYCIE I ZDROWIE | B43: Prywatne wizyty lekarskie | C43: ='Budżet 2026'!C43*(1+#REF!) -> #REF! | D43: ='Budżet 2026'!D43*(1+#REF!) -> #REF! | E43: ='Budżet 2026'!E43*(1+#REF!) -> #REF! | F43: ='Budżet 2026'!F43*(1+#REF!) -> #REF! | G43: ='Budżet 2026'!G43*(1+#REF!) -> #REF! | H43: ='Budżet 2026'!H43*(1+#REF!) -> #REF! | I43: ='Budżet 2026'!I43*(1+#REF!) -> #REF! | J43: ='Budżet 2026'!J43*(1+#REF!) -> #REF! | ... N43: ='Budżet 2026'!N43*(1+#REF!) -> #REF! | O43: =SUM(C43:N43) -> #REF!
...
